Unhandled exception in thread started by <function wrapper at 0x0000000003D246D8>
Traceback (most recent call last):
  File "C:\Users\gchicafernandez\AppData\Local\Continuum\Anaconda2\lib\site-packages\django\utils\autoreload.py", line 227, in wrapper
    fn(*args, **kwargs)
  File "C:\Users\gchicafernandez\AppData\Local\Continuum\Anaconda2\lib\site-packages\django\core\management\commands\runserver.py", line 117, in inner_run
    autoreload.raise_last_exception()
  File "C:\Users\gchicafernandez\AppData\Local\Continuum\Anaconda2\lib\site-packages\django\utils\autoreload.py", line 250, in raise_last_exception
    six.reraise(*_exception)
  File "C:\Users\gchicafernandez\AppData\Local\Continuum\Anaconda2\lib\site-packages\django\utils\autoreload.py", line 227, in wrapper
    fn(*args, **kwargs)
  File "C:\Users\gchicafernandez\AppData\Local\Continuum\Anaconda2\lib\site-packages\django\__init__.py", line 27, in setup
    apps.populate(settings.INSTALLED_APPS)
  File "C:\Users\gchicafernandez\AppData\Local\Continuum\Anaconda2\lib\site-packages\django\apps\registry.py", line 85, in populate
    app_config = AppConfig.create(entry)
  File "C:\Users\gchicafernandez\AppData\Local\Continuum\Anaconda2\lib\site-packages\django\apps\config.py", line 94, in create
    module = import_module(entry)
  File "C:\Users\gchicafernandez\AppData\Local\Continuum\Anaconda2\lib\importlib\__init__.py", line 37, in import_module
    __import__(name)
ImportError: No module named corsheaders
